Workbook

Sheet games
A1: 遊戲名稱 | B1: Logo | C1: Facebook | D1: 官方網站 | E1: App Store | F1: 禮包碼 | G1: GooglePlay | H1: canonical_url | I1: 簡介 | J1: 商品1名稱 | K1: 商品1價格 | L1: 商品2名稱 | M1: 商品2價格 | N1: 商品3名稱 | O1: 商品3價格 | P1: 商品4名稱 | Q1: 商品4價格 | R1: 商品5名稱 | S1: 商品5價格 | T1: 商品6名稱 | U1: 商品6價格 | V1: 商品7名稱 | W1: 商品7價格 | X1: 商品8名稱 | Y1: 商品8價格 | Z1: 商品9名稱 | AA1: 商品9價格 | AB1: 商品10名稱 | AC1: 商品10價格 | AD1: 商品11名稱 | AE1: 商品11價格 | AF1: 商品12名稱 | AG1: 商品12價格 | AH1: 商品13名稱 | AI1: 商品13價格 | AJ1: 商品14名稱 | AK1: 商品14價格 | AL1: 商品15名稱 | AM1: 商品15價格
A2: 巔峰極速 | F2: =IF(A2="","", "https://www.ssbuy.tw/detail_giftcode/dist/giftcodes/" & IF(ISNUMBER(LEFT(A2,1)*1), "game-", "") & A2 & ".html") -> https://www.ssbuy.tw/detail_giftcode/dist/giftcodes/巔峰極速.html | H2: =IF(A2="","", "https://www.ssbuy.tw/detail_giftcode/dist/gamedetail/" & IF(ISNUMBER(LEFT(A2,1)*1), "game-", "") & A2 & ".html") -> https://www.ssbuy.tw/detail_giftcode/dist/gamedetail/巔峰極速.html | I2: 《巔峰極速》是與Codemasters®深度合作, 3A級巔峰品質擬真競速遊戲。 玩家可以自由收集、改裝超過100款正版授權的豪華車輛，馳騁在全世界的街道與專業賽道上，感受極致光影與真實轟鳴聲帶來的沉浸體驗，更擁有豐富的競速玩法，立即加入與其他玩家進行即時競速對決，突破賽車的速度極限！ | J2: 鑽石 60顆 | K2: 30 | L2: 鑽石 300顆 | M2: 137 | N2: 鑽石 680顆 | O2: 260 | P2: 鑽石 980顆 | Q2: 390 | R2: 鑽石 1280顆 | S2: 520 | T2: 鑽石 1980顆 | U2: 780 | V2: 鑽石 3280顆 | W2: 1300 | X2: 鑽石6480顆 | Y2: 2395 | Z2: 月卡 | AA2: 137 | AB2: 高級合約 | AC2: 260 | AD2: 特級合約 | AE2: 520 | AF2: 合約組合禮包 | AG2: 1260 | AH2: 合約組合禮包(折扣) | AI2: 1150
A3: 原神 | F3: =IF(A3="","", "https://www.ssbuy.tw/detail_giftcode/dist/giftcodes/" & IF(ISNUMBER(LEFT(A3,1)*1), "game-", "") & A3 & ".html") -> https://www.ssbuy.tw/detail_giftcode/dist/giftcodes/原神.html | H3: =IF(A3="","", "https://www.ssbuy.tw/detail_giftcode/dist/gamedetail/" & IF(ISNUMBER(LEFT(A3,1)*1), "game-", "") & A3 & ".html") -> https://www.ssbuy.tw/detail_giftcode/dist/gamedetail/原神.html | I3: 《原神》是一款開放世界冒險角色扮演遊戲。 踏上跨越奇幻世界提瓦特大陸的旅程。 在這個廣闊世界中，探索七個國家，遇到擁有獨特性格和能力的不同角色，並與他們一起對抗強大的敵人，並同時尋找您失散的手足。 自由冒險，沈浸在充滿生命力的世界中，讓好奇心引領您揭開它所有的神秘面紗。 | J3: 創世結晶 60顆 | K3: 30 | L3: 創世結晶 300顆 | M3: 137 | N3: 創世結晶 980顆 | O3: 390 | P3: 創世結晶 1980顆 | Q3: 780 | R3: 創世結晶 3280顆 | S3: 1300 | T3: 創世結晶 6480顆 | U3: 2350 | V3: 空月祝福 | W3: 137 | X3: 珍珠紀行 | Y3: 260 | Z3: 珍珠之歌 | AA3: 520
A4: 極速快感 | F4: =IF(A4="","", "https://www.ssbuy.tw/detail_giftcode/dist/giftcodes/" & IF(ISNUMBER(LEFT(A4,1)*1), "game-", "") & A4 & ".html") -> https://www.ssbuy.tw/detail_giftcode/dist/giftcodes/極速快感.html | H4: =IF(A4="","", "https://www.ssbuy.tw/detail_giftcode/dist/gamedetail/" & IF(ISNUMBER(LEFT(A4,1)*1), "game-", "") & A4 & ".html") -> https://www.ssbuy.tw/detail_giftcode/dist/gamedetail/極速快感.html | I4: 《極速快感：集結》（英語：Need for Speed Mobile，中國大陸譯作「極品飛車：集結」）是一款由騰訊遊戲旗下天美工作室群開發、美商藝電發行的開放世界競速手機遊戲，台灣、香港和澳門地區由Garena代理發行。 | J4: 66點券 | K4: 35 | L4: 340點券 | M4: 137 | N4: 660點券 | O4: 264 | P4: 980點券 | Q4: 394 | R4: 1980點券 | S4: 786 | T4: 2580點券 | U4: 1130 | V4: 3380點券 | W4: 1323 | X4: 6580點券 | Y4: 2551 | Z4: 月卡 | AA4: 137 | AB4: 普通通行證 | AC4: 270 | AD4: 豪華通行證 | AE4: 540 | AF4: 超值理財 | AG4: 267
A5: 俠客傳說：小小英雄 | F5: =IF(A5="","", "https://www.ssbuy.tw/detail_giftcode/dist/giftcodes/" & IF(ISNUMBER(LEFT(A5,1)*1), "game-", "") & A5 & ".html") -> https://www.ssbuy.tw/detail_giftcode/dist/giftcodes/俠客傳說：小小英雄.html | H5: =IF(A5="","", "https://www.ssbuy.tw/detail_giftcode/dist/gamedetail/" & IF(ISNUMBER(LEFT(A5,1)*1), "game-", "") & A5 & ".html") -> https://www.ssbuy.tw/detail_giftcode/dist/gamedetail/俠客傳說：小小英雄.html | I5: 有你的地方，就有江湖。 | J5: 9999仙玉 | K5: 8300 | L5: 3290仙玉 | M5: 2551 | N5: 1690仙玉 | O5: 1323 | P5: 670仙玉 | Q5: 539 | R5: 330仙玉 | S5: 267 | T5: 170仙玉 | U5: 137 | V5: 33仙玉 | W5: 40
A6: 逆水寒 | F6: =IF(A6="","", "https://www.ssbuy.tw/detail_giftcode/dist/giftcodes/" & IF(ISNUMBER(LEFT(A6,1)*1), "game-", "") & A6 & ".html") -> https://www.ssbuy.tw/detail_giftcode/dist/giftcodes/逆水寒.html | H6: =IF(A6="","", "https://www.ssbuy.tw/detail_giftcode/dist/gamedetail/" & IF(ISNUMBER(LEFT(A6,1)*1), "game-", "") & A6 & ".html") -> https://www.ssbuy.tw/detail_giftcode/dist/gamedetail/逆水寒.html | I6: 新武俠大世界冒險RPG《俠客傳說：小小英雄》 | J6: 6480玉 | K6: 2390 | L6: 3280玉 | M6: 1323 | N6: 1980玉 | O6: 810 | P6: 980玉 | Q6: 410 | R6: 300玉 | S6: 137 | T6: 60玉 | U6: 30
A7: RO仙境傳說：一定要可愛 | F7: =IF(A7="","", "https://www.ssbuy.tw/detail_giftcode/dist/giftcodes/" & IF(ISNUMBER(LEFT(A7,1)*1), "game-", "") & A7 & ".html") -> https://www.ssbuy.tw/detail_giftcode/dist/giftcodes/RO仙境傳說：一定要可愛.html | H7: =IF(A7="","", "https://www.ssbuy.tw/detail_giftcode/dist/gamedetail/" & IF(ISNUMBER(LEFT(A7,1)*1), "game-", "") & A7 & ".html") -> https://www.ssbuy.tw/detail_giftcode/dist/gamedetail/RO仙境傳說：一定要可愛.html | I7: 可不可愛？我們說了算！ | J7: 4500鑽 | K7: 2551 | L7: 3000鑽 | M7: 1720 | N7: 1500鑽 | O7: 786 | P7: 750鑽 | Q7: 394 | R7: 450鑽 | S7: 267 | T7: 225鑽 | U7: 137 | V7: 75鑽 | W7: 50
A8: RO新世代 | F8: =IF(A8="","", "https://www.ssbuy.tw/detail_giftcode/dist/giftcodes/" & IF(ISNUMBER(LEFT(A8,1)*1), "game-", "") & A8 & ".html") -> https://www.ssbuy.tw/detail_giftcode/dist/giftcodes/RO新世代.html | H8: =IF(A8="","", "https://www.ssbuy.tw/detail_giftcode/dist/gamedetail/" & IF(ISNUMBER(LEFT(A8,1)*1), "game-", "") & A8 & ".html") -> https://www.ssbuy.tw/detail_giftcode/dist/gamedetail/RO新世代.html | I8: 官方正版RO最新作「RO仙境傳説：新世代的誕生」，煥新啓航！不刪檔公測開啟！ | J8: 3290商品 | K8: 2551 | L8: 1690商品 | M8: 1323 | N8: 990商品 | O8: 786 | P8: 670商品 | Q8: 539 | R8: 330商品 | S8: 267 | T8: 170商品 | U8: 137 | V8: 33商品 | W8: 35
A9: 上古：龍神覺醒 | F9: =IF(A9="","", "https://www.ssbuy.tw/detail_giftcode/dist/giftcodes/" & IF(ISNUMBER(LEFT(A9,1)*1), "game-", "") & A9 & ".html") -> https://www.ssbuy.tw/detail_giftcode/dist/giftcodes/上古：龍神覺醒.html | H9: =IF(A9="","", "https://www.ssbuy.tw/detail_giftcode/dist/gamedetail/" & IF(ISNUMBER(LEFT(A9,1)*1), "game-", "") & A9 & ".html") -> https://www.ssbuy.tw/detail_giftcode/dist/gamedetail/上古：龍神覺醒.html | I9: 首款龍主題MMO鉅作！ | J9: 9999紅寶石 | K9: 2551 | L9: 4999紅寶石 | M9: 1380 | N9: 2999紅寶石 | O9: 830 | P9: 1999紅寶石 | Q9: 539 | R9: 1499紅寶石 | S9: 394 | T9: 999紅寶石 | U9: 267 | V9: 499紅寶石 | W9: 137 | X9: 99紅寶石 | Y9: 35
A10: 小艦艦超勇 | F10: =IF(A10="","", "https://www.ssbuy.tw/detail_giftcode/dist/giftcodes/" & IF(ISNUMBER(LEFT(A10,1)*1), "game-", "") & A10 & ".html") -> https://www.ssbuy.tw/detail_giftcode/dist/giftcodes/小艦艦超勇.html | H10: =IF(A10="","", "https://www.ssbuy.tw/detail_giftcode/dist/gamedetail/" & IF(ISNUMBER(LEFT(A10,1)*1), "game-", "") & A10 & ".html") -> https://www.ssbuy.tw/detail_giftcode/dist/gamedetail/小艦艦超勇.html | I10: 無止境的武器升級，打造你的最強艦隊！ | J10: 9999冰海水晶 | K10: 2551 | L10: 4999冰海水晶 | M10: 1323 | N10: 1999冰海水晶 | O10: 539 | P10: 999冰海水晶 | Q10: 267 | R10: 499冰海水晶 | S10: 137 | T10: 99冰海水晶 | U10: 40
A11: 天使軍團 | F11: =IF(A11="","", "https://www.ssbuy.tw/detail_giftcode/dist/giftcodes/" & IF(ISNUMBER(LEFT(A11,1)*1), "game-", "") & A11 & ".html") -> https://www.ssbuy.tw/detail_giftcode/dist/giftcodes/天使軍團.html | H11: =IF(A11="","", "https://www.ssbuy.tw/detail_giftcode/dist/gamedetail/" & IF(ISNUMBER(LEFT(A11,1)*1), "game-", "") & A11 & ".html") -> https://www.ssbuy.tw/detail_giftcode/dist/gamedetail/天使軍團.html | I11: 天使軍團是最新推出的3D天使銀河冒險RPG手遊。 希拉星系，深邃而瑰麗……這裡曾存在著古老時期的文明。 | J11: 3290商品 | K11: 2551 | L11: 1690商品 | M11: 1323 | N11: 990商品 | O11: 786 | P11: 670商品 | Q11: 539 | R11: 330商品 | S11: 267 | T11: 170商品 | U11: 137 | V11: 33商品 | W11: 35
A12: 天堂W | F12: =IF(A12="","", "https://www.ssbuy.tw/detail_giftcode/dist/giftcodes/" & IF(ISNUMBER(LEFT(A12,1)*1), "game-", "") & A12 & ".html") -> https://www.ssbuy.tw/detail_giftcode/dist/giftcodes/天堂W.html | H12: =IF(A12="","", "https://www.ssbuy.tw/detail_giftcode/dist/gamedetail/" & IF(ISNUMBER(LEFT(A12,1)*1), "game-", "") & A12 & ".html") -> https://www.ssbuy.tw/detail_giftcode/dist/gamedetail/天堂W.html | I12: 《天堂W》是繼承PC MMORPG天堂正統性的跨平台遊戲，全球單一版本服務，即時AI翻譯；Full 3D畫面和斜45度視角開發的暗黑奇幻世界；將天堂的核心內容戰鬥社群延伸到世界。 | J12: 5900商品 | K12: 5300 | L12: 2600商品 | M12: 2360 | N12: 1300商品 | O12: 1180 | P12: 780商品 | Q12: 730 | R12: 260商品 | S12: 250
A13: 少女前線2：追放 | F13: =IF(A13="","", "https://www.ssbuy.tw/detail_giftcode/dist/giftcodes/" & IF(ISNUMBER(LEFT(A13,1)*1), "game-", "") & A13 & ".html") -> https://www.ssbuy.tw/detail_giftcode/dist/giftcodes/少女前線2：追放.html | H13: =IF(A13="","", "https://www.ssbuy.tw/detail_giftcode/dist/gamedetail/" & IF(ISNUMBER(LEFT(A13,1)*1), "game-", "") & A13 & ".html") -> https://www.ssbuy.tw/detail_giftcode/dist/gamedetail/少女前線2：追放.html | I13: 講述了指揮官與格里芬之間無法調和的理念衝突，導致指揮官選擇自我流放，成為賞金獵人。 | J13: 3290商品 | K13: 2551 | L13: 1690商品 | M13: 1323 | N13: 990商品 | O13: 786 | P13: 670商品 | Q13: 539 | R13: 330商品 | S13: 267 | T13: 170商品 | U13: 137 | V13: 33商品 | W13: 35
A14: 幻獸傳說Ｍ | F14: =IF(A14="","", "https://www.ssbuy.tw/detail_giftcode/dist/giftcodes/" & IF(ISNUMBER(LEFT(A14,1)*1), "game-", "") & A14 & ".html") -> https://www.ssbuy.tw/detail_giftcode/dist/giftcodes/幻獸傳說Ｍ.html | H14: =IF(A14="","", "https://www.ssbuy.tw/detail_giftcode/dist/gamedetail/" & IF(ISNUMBER(LEFT(A14,1)*1), "game-", "") & A14 & ".html") -> https://www.ssbuy.tw/detail_giftcode/dist/gamedetail/幻獸傳說Ｍ.html | I14: 2025年萬眾期待的幻獸手遊來啦！異世界捉獸育獸RPG《幻獸傳說M》現已上市！豆花蔡黃汝可愛代言，演繹疾海兔！ | J14: 6488彩鑽 | K14: 2551 | L14: 3280彩鑽 | M14: 1323 | N14: 1980彩鑽 | O14: 786 | P14: 1280彩鑽 | Q14: 539 | R14: 980彩鑽 | S14: 394 | T14: 680彩鑽 | U14: 267 | V14: 300彩鑽 | W14: 137 | X14: 60彩鑽 | Y14: 35
A15: 未定事件簿 | F15: =IF(A15="","", "https://www.ssbuy.tw/detail_giftcode/dist/giftcodes/" & IF(ISNUMBER(LEFT(A15,1)*1), "game-", "") & A15 & ".html") -> https://www.ssbuy.tw/detail_giftcode/dist/giftcodes/未定事件簿.html | H15: =IF(A15="","", "https://www.ssbuy.tw/detail_giftcode/dist/gamedetail/" & IF(ISNUMBER(LEFT(A15,1)*1), "game-", "") & A15 & ".html") -> https://www.ssbuy.tw/detail_giftcode/dist/gamedetail/未定事件簿.html | I15: 當正義與邪惡的界定越來越模糊，妳手中的天平將會傾向何方？一場戀愛與推理的冒險，此刻，邀妳共赴。 | J15: 3290商品 | K15: 2551 | L15: 1690商品 | M15: 1323 | N15: 990商品 | O15: 786 | P15: 670商品 | Q15: 539 | R15: 330商品 | S15: 267 | T15: 170商品 | U15: 137 | V15: 33商品 | W15: 35
A16: 永恆靈魂 | F16: =IF(A16="","", "https://www.ssbuy.tw/detail_giftcode/dist/giftcodes/" & IF(ISNUMBER(LEFT(A16,1)*1), "game-", "") & A16 & ".html") -> https://www.ssbuy.tw/detail_giftcode/dist/giftcodes/永恆靈魂.html | H16: =IF(A16="","", "https://www.ssbuy.tw/detail_giftcode/dist/gamedetail/" & IF(ISNUMBER(LEFT(A16,1)*1), "game-", "") & A16 & ".html") -> https://www.ssbuy.tw/detail_giftcode/dist/gamedetail/永恆靈魂.html | I16: 末日的今天，精靈們等候您的指示…救援者，帶領著她們的靈魂活下去吧。 | J16: 3290商品 | K16: 2551 | L16: 1690商品 | M16: 1323 | N16: 990商品 | O16: 786 | P16: 670商品 | Q16: 539 | R16: 330商品 | S16: 267 | T16: 170商品 | U16: 137 | V16: 33商品 | W16: 35
A17: 守住呀主公 | F17: =IF(A17="","", "https://www.ssbuy.tw/detail_giftcode/dist/giftcodes/" & IF(ISNUMBER(LEFT(A17,1)*1), "game-", "") & A17 & ".html") -> https://www.ssbuy.tw/detail_giftcode/dist/giftcodes/守住呀主公.html | H17: =IF(A17="","", "https://www.ssbuy.tw/detail_giftcode/dist/gamedetail/" & IF(ISNUMBER(LEFT(A17,1)*1), "game-", "") & A17 & ".html") -> https://www.ssbuy.tw/detail_giftcode/dist/gamedetail/守住呀主公.html | I17: 喜歡策略塔防、鍾愛三國名將的你，絕對不容錯過這款高畫質3D塔防力作！豐富的塔防玩法、酷炫的技能特效，讓你盡享爽快的遊戲體驗。 | J17: 6000元寶 | K17: 2551 | L17: 3000元寶 | M17: 1323 | N17: 1800元寶 | O17: 786 | P17: 1200元寶 | Q17: 539 | R17: 900元寶 | S17: 394 | T17: 600元寶 | U17: 267 | V17: 300元寶 | W17: 137 | X17: 60元寶 | Y17: 30
A18: 吟遊戰記 | F18: =IF(A18="","", "https://www.ssbuy.tw/detail_giftcode/dist/giftcodes/" & IF(ISNUMBER(LEFT(A18,1)*1), "game-", "") & A18 & ".html") -> https://www.ssbuy.tw/detail_giftcode/dist/giftcodes/吟遊戰記.html | H18: =IF(A18="","", "https://www.ssbuy.tw/detail_giftcode/dist/gamedetail/" & IF(ISNUMBER(LEFT(A18,1)*1), "game-", "") & A18 & ".html") -> https://www.ssbuy.tw/detail_giftcode/dist/gamedetail/吟遊戰記.html | I18: 新感覺放置型勇者冒險RPG，登入即可獲得免費9999連抽！輕鬆休閒的冒險，來一場解放雙手的戰鬥吧！ | J18: 6480鑽石 | K18: 2551 | L18: 3280鑽石 | M18: 1323 | N18: 1980鑽石 | O18: 786 | P18: 1280鑽石 | Q18: 539 | R18: 980鑽石 | S18: 394 | T18: 680鑽石 | U18: 267 | V18: 300鑽石 | W18: 137 | X18: 60鑽石 | Y18: 30
A19: 我獨自升級：ARISE | F19: =IF(A19="","", "https://www.ssbuy.tw/detail_giftcode/dist/giftcodes/" & IF(ISNUMBER(LEFT(A19,1)*1), "game-", "") & A19 & ".html") -> https://www.ssbuy.tw/detail_giftcode/dist/giftcodes/我獨自升級：ARISE.html | H19: =IF(A19="","", "https://www.ssbuy.tw/detail_giftcode/dist/gamedetail/" & IF(ISNUMBER(LEFT(A19,1)*1), "game-", "") & A19 & ".html") -> https://www.ssbuy.tw/detail_giftcode/dist/gamedetail/我獨自升級：ARISE.html | I19: 德國最強的獵人，也是世界獵人排名第12名的S級「萊納德．尼爾曼」已加入完成！ | J19: 8700鑽 | K19: 1940 | L19: 4750鑽 | M19: 1150 | N19: 2600鑽 | O19: 620 | P19: 1150鑽 | Q19: 267 | R19: 335鑽 | S19: 90 | T19: 110鑽 | U19: 30
A20: 命運聖契：少女的羈絆 | F20: =IF(A20="","", "https://www.ssbuy.tw/detail_giftcode/dist/giftcodes/" & IF(ISNUMBER(LEFT(A20,1)*1), "game-", "") & A20 & ".html") -> https://www.ssbuy.tw/detail_giftcode/dist/giftcodes/命運聖契：少女的羈絆.html | H20: =IF(A20="","", "https://www.ssbuy.tw/detail_giftcode/dist/gamedetail/" & IF(ISNUMBER(LEFT(A20,1)*1), "game-", "") & A20 & ".html") -> https://www.ssbuy.tw/detail_giftcode/dist/gamedetail/命運聖契：少女的羈絆.html | I20: 2025首款命運少女輕放置RPG手遊《命運聖契：少女的羈絆》霜糖奇典活动開啟！登錄可得自選SSR、限定頭像框及海量高價值虛寶。 | J20: 6480星鑽 | K20: 2551 | L20: 3280星鑽 | M20: 1323 | N20: 1980星鑽 | O20: 786 | P20: 980星鑽 | Q20: 394 | R20: 300星鑽 | S20: 137 | T20: 60星鑽 | U20: 40
A21: 放置軍團 | F21: =IF(A21="","", "https://www.ssbuy.tw/detail_giftcode/dist/giftcodes/" & IF(ISNUMBER(LEFT(A21,1)*1), "game-", "") & A21 & ".html") -> https://www.ssbuy.tw/detail_giftcode/dist/giftcodes/放置軍團.html | H21: =IF(A21="","", "https://www.ssbuy.tw/detail_giftcode/dist/gamedetail/" & IF(ISNUMBER(LEFT(A21,1)*1), "game-", "") & A21 & ".html") -> https://www.ssbuy.tw/detail_giftcode/dist/gamedetail/放置軍團.html | I21: 我們敬愛的魔王大人在與人類的決戰中，因為死亡騎士臨陣倒戈，被人類打碎成了渣渣。我們三個忠心耿耿的小鬼抬著魔王的靈魂碎片，躲進了一座廢棄的地下城。在這裡我們要重新建立地下城，儲備物資，集結軍團！ | J21: 6480氪晶 | K21: 2540 | L21: 3280氪晶 | M21: 1280 | N21: 1280氪晶 | O21: 539 | P21: 680氪晶 | Q21: 267 | R21: 300氪晶 | S21: 137
A22: 明日方舟 | F22: =IF(A22="","", "https://www.ssbuy.tw/detail_giftcode/dist/giftcodes/" & IF(ISNUMBER(LEFT(A22,1)*1), "game-", "") & A22 & ".html") -> https://www.ssbuy.tw/detail_giftcode/dist/giftcodes/明日方舟.html | H22: =IF(A22="","", "https://www.ssbuy.tw/detail_giftcode/dist/gamedetail/" & IF(ISNUMBER(LEFT(A22,1)*1), "game-", "") & A22 & ".html") -> https://www.ssbuy.tw/detail_giftcode/dist/gamedetail/明日方舟.html | I22: 迷宮裡……竟然存在這樣的地方？準備好刀劍和法杖，也別忘了鍋、鏟和調味料！準備好了嗎，我們要開動了喔！ | J22: 3290商品 | K22: 2551 | L22: 1690商品 | M22: 1323 | N22: 990商品 | O22: 786 | P22: 670商品 | Q22: 539 | R22: 330商品 | S22: 267 | T22: 170商品 | U22: 137 | V22: 33商品 | W22: 35
A23: 屍鬼三國 | F23: =IF(A23="","", "https://www.ssbuy.tw/detail_giftcode/dist/giftcodes/" & IF(ISNUMBER(LEFT(A23,1)*1), "game-", "") & A23 & ".html") -> https://www.ssbuy.tw/detail_giftcode/dist/giftcodes/屍鬼三國.html | H23: =IF(A23="","", "https://www.ssbuy.tw/detail_giftcode/dist/gamedetail/" & IF(ISNUMBER(LEFT(A23,1)*1), "game-", "") & A23 & ".html") -> https://www.ssbuy.tw/detail_giftcode/dist/gamedetail/屍鬼三國.html | I23: 獨一款屍鬼化的三國卡牌手遊上市啦！新世代三國卡牌鉅作，融合了ARPG的開放世界設計，你可以在屍鬼橫行的三國亂世中自由探索。 | J23: 6000金玉 | K23: 2551 | L23: 3000金玉 | M23: 1323 | N23: 1800金玉 | O23: 786 | P23: 900金玉 | Q23: 394 | R23: 300金玉 | S23: 137 | T23: 60金玉 | U23: 30
A24: 星鏈計畫：未來少女 | F24: =IF(A24="","", "https://www.ssbuy.tw/detail_giftcode/dist/giftcodes/" & IF(ISNUMBER(LEFT(A24,1)*1), "game-", "") & A24 & ".html") -> https://www.ssbuy.tw/detail_giftcode/dist/giftcodes/星鏈計畫：未來少女.html | H24: =IF(A24="","", "https://www.ssbuy.tw/detail_giftcode/dist/gamedetail/" & IF(ISNUMBER(LEFT(A24,1)*1), "game-", "") & A24 & ".html") -> https://www.ssbuy.tw/detail_giftcode/dist/gamedetail/星鏈計畫：未來少女.html | I24: 在無盡的絕望中，為少女們構築希望藍圖！ | J24: 5500星際比特 | K24: 2150 | L24: 4400星際比特 | M24: 1750 | N24: 2750星際比特 | O24: 1130 | P24: 1650星際比特 | Q24: 700 | R24: 750星際比特 | S24: 340 | T24: 165星際比特 | U24: 90
A25: 英雄之王 | F25: =IF(A25="","", "https://www.ssbuy.tw/detail_giftcode/dist/giftcodes/" & IF(ISNUMBER(LEFT(A25,1)*1), "game-", "") & A25 & ".html") -> https://www.ssbuy.tw/detail_giftcode/dist/giftcodes/英雄之王.html | H25: =IF(A25="","", "https://www.ssbuy.tw/detail_giftcode/dist/gamedetail/" & IF(ISNUMBER(LEFT(A25,1)*1), "game-", "") & A25 & ".html") -> https://www.ssbuy.tw/detail_giftcode/dist/gamedetail/英雄之王.html | I25: 除了我們分享的遊戲畫面、影片和其他細節之外，我還想讓大家了解我們對遊戲的期望與願景。 我們希望能藉由《英雄之王》捕捉遊戲的本質。 | J25: 3290商品 | K25: 2551 | L25: 1690商品 | M25: 1323 | N25: 990商品 | O25: 786 | P25: 670商品 | Q25: 539 | R25: 330商品 | S25: 267 | T25: 170商品 | U25: 137 | V25: 33商品 | W25: 35
A26: 英雄聯盟 | F26: =IF(A26="","", "https://www.ssbuy.tw/detail_giftcode/dist/giftcodes/" & IF(ISNUMBER(LEFT(A26,1)*1), "game-", "") & A26 & ".html") -> https://www.ssbuy.tw/detail_giftcode/dist/giftcodes/英雄聯盟.html | H26: =IF(A26="","", "https://www.ssbuy.tw/detail_giftcode/dist/gamedetail/" & IF(ISNUMBER(LEFT(A26,1)*1), "game-", "") & A26 & ".html") -> https://www.ssbuy.tw/detail_giftcode/dist/gamedetail/英雄聯盟.html | I26: 別再讓老媽扛傷害了 | J26: 12150聯盟幣 | K26: 2420 | L26: 7050聯盟幣 | M26: 1323 | N26: 3500聯盟幣 | O26: 740 | P26: 1380聯盟幣 | Q26: 267 | R26: 660聯盟幣 | S26: 137
A27: 恐龍突變 | F27: =IF(A27="","", "https://www.ssbuy.tw/detail_giftcode/dist/giftcodes/" & IF(ISNUMBER(LEFT(A27,1)*1), "game-", "") & A27 & ".html") -> https://www.ssbuy.tw/detail_giftcode/dist/giftcodes/恐龍突變.html | H27: =IF(A27="","", "https://www.ssbuy.tw/detail_giftcode/dist/gamedetail/" & IF(ISNUMBER(LEFT(A27,1)*1), "game-", "") & A27 & ".html") -> https://www.ssbuy.tw/detail_giftcode/dist/gamedetail/恐龍突變.html | I27: » 配對以產生受精卵: 進行戰略性交配以創造更強大的恐龍。» 點擊孵化無限的蛋: 不斷擴展你的恐龍收藏。 | J27: 1490商品 | K27: 1323 | L27: 1290商品 | M27: 1120 | N27: 990商品 | O27: 786 | P27: 790商品 | Q27: 680 | R27: 690商品 | S27: 539 | T27: 490商品 | U27: 394 | V27: 320商品 | W27: 267 | X27: 190商品 | Y27: 170
A28: 神域 | F28: =IF(A28="","", "https://www.ssbuy.tw/detail_giftcode/dist/giftcodes/" & IF(ISNUMBER(LEFT(A28,1)*1), "game-", "") & A28 & ".html") -> https://www.ssbuy.tw/detail_giftcode/dist/giftcodes/神域.html | H28: =IF(A28="","", "https://www.ssbuy.tw/detail_giftcode/dist/gamedetail/" & IF(ISNUMBER(LEFT(A28,1)*1), "game-", "") & A28 & ".html") -> https://www.ssbuy.tw/detail_giftcode/dist/gamedetail/神域.html | I28: 對抗邪惡勢力，策略過人的您並非孤軍奮戰，來自世界各地且為數眾多的神話英雄，正等待您的召喚！透過遊戲掛機得到的寶石、材料及各種資源，一支強而有力且技能靈活的自訂專屬軍團，就在您的股掌之間！ | J28: 3290商品 | K28: 2551 | L28: 1690商品 | M28: 1323 | N28: 990商品 | O28: 786 | P28: 670商品 | Q28: 539 | R28: 330商品 | S28: 267 | T28: 170商品 | U28: 137 | V28: 33商品 | W28: 35
A29: 崩壞：星穹鐵道 | F29: =IF(A29="","", "https://www.ssbuy.tw/detail_giftcode/dist/giftcodes/" & IF(ISNUMBER(LEFT(A29,1)*1), "game-", "") & A29 & ".html") -> https://www.ssbuy.tw/detail_giftcode/dist/giftcodes/崩壞：星穹鐵道.html | H29: =IF(A29="","", "https://www.ssbuy.tw/detail_giftcode/dist/gamedetail/" & IF(ISNUMBER(LEFT(A29,1)*1), "game-", "") & A29 & ".html") -> https://www.ssbuy.tw/detail_giftcode/dist/gamedetail/崩壞：星穹鐵道.html | I29: 這片銀河中有名為「星神」的存在，祂們造就現實，抹消星辰，在無數「世界」中留下祂們的痕跡。你——一名特殊的旅客，將偕同繼承「開拓」意志的同伴們，乘坐星穹列車穿越銀河，沿著某位「星神」曾經所行之途前進。你將由此探索新的文明、結識新的夥伴、在無數光怪陸離的「世界」之間展開新的冒險。所有你想知道的，都將在群星中找到解答。 那麼，準備好開始這段「開拓」之旅了嗎？ | J29: 6480古老夢華 | K29: 2320 | L29: 3280古老夢華 | M29: 1250 | N29: 1980古老夢華 | O29: 790 | P29: 980古老夢華 | Q29: 394 | R29: 300古老夢華 | S29: 137 | T29: 60古老夢華 | U29: 30 | V29: 列車補給憑證 | W29: 137 | X29: 無名客的榮勳 | Y29: 260 | Z29: 無名客的獎章 | AA29: 520
A30: 救世者之樹：新世界 | F30: =IF(A30="","", "https://www.ssbuy.tw/detail_giftcode/dist/giftcodes/" & IF(ISNUMBER(LEFT(A30,1)*1), "game-", "") & A30 & ".html") -> https://www.ssbuy.tw/detail_giftcode/dist/giftcodes/救世者之樹：新世界.html | H30: =IF(A30="","", "https://www.ssbuy.tw/detail_giftcode/dist/gamedetail/" & IF(ISNUMBER(LEFT(A30,1)*1), "game-", "") & A30 & ".html") -> https://www.ssbuy.tw/detail_giftcode/dist/gamedetail/救世者之樹：新世界.html | I30: 在重磅上線的樹緣系統中，舉行浪漫的樹緣典禮；集結戰友做好準備，迎戰魔神副本BOSS！ 新手可領取70抽、金色時裝4件套還有限定自選坐騎！ 讓我們來看看來自亞洲11地區的勇者們的留言！ -「日本韓國泰國的妹妹都搶著跟我結緣…好難選哦！」 --來自世界頻道的建巨集007號 樹緣系統重磅上線，在全服玩家的見證和祝福下，完成盛大浪漫的樹緣典禮！還會擁有一個共同的家園，一起創造美好生活！ | J30: 3290商品 | K30: 2551 | L30: 1690商品 | M30: 1323 | N30: 990商品 | O30: 786 | P30: 670商品 | Q30: 539 | R30: 330商品 | S30: 267 | T30: 170商品 | U30: 137 | V30: 33商品 | W30: 35
A31: 球球英雄 | F31: =IF(A31="","", "https://www.ssbuy.tw/detail_giftcode/dist/giftcodes/" & IF(ISNUMBER(LEFT(A31,1)*1), "game-", "") & A31 & ".html") -> https://www.ssbuy.tw/detail_giftcode/dist/giftcodes/球球英雄.html | H31: =IF(A31="","", "https://www.ssbuy.tw/detail_giftcode/dist/gamedetail/" & IF(ISNUMBER(LEFT(A31,1)*1), "game-", "") & A31 & ".html") -> https://www.ssbuy.tw/detail_giftcode/dist/gamedetail/球球英雄.html | I31: 怪物們在這一天毫無預兆地突然降臨，城市與家園都籠罩在猙獰與陰霾中。 我們需要你，勇士！為我們抵禦黑暗勢力！ 來吧！和我們一起，召喚出賦有神奇力量的球球，與黑暗勢力戰鬥！ | J31: 3290商品 | K31: 2551 | L31: 1690商品 | M31: 1390 | N31: 990商品 | O31: 786 | P31: 670商品 | Q31: 539 | R31: 330商品 | S31: 267 | T31: 170商品 | U31: 137 | V31: 33商品 | W31: 35
A32: 第七史詩 | F32: =IF(A32="","", "https://www.ssbuy.tw/detail_giftcode/dist/giftcodes/" & IF(ISNUMBER(LEFT(A32,1)*1), "game-", "") & A32 & ".html") -> https://www.ssbuy.tw/detail_giftcode/dist/giftcodes/第七史詩.html | H32: =IF(A32="","", "https://www.ssbuy.tw/detail_giftcode/dist/gamedetail/" & IF(ISNUMBER(LEFT(A32,1)*1), "game-", "") & A32 & ".html") -> https://www.ssbuy.tw/detail_giftcode/dist/gamedetail/第七史詩.html | I32: 第七個世界的故事...生命的女神迪彩將自己的權勢瓜分，創造出聖約的繼承者及神獸 | J32: 3290商品 | K32: 2551 | L32: 1690商品 | M32: 1390 | N32: 990商品 | O32: 786 | P32: 670商品 | Q32: 539 | R32: 330商品 | S32: 267 | T32: 170商品 | U32: 137 | V32: 33商品 | W32: 35
A33: 創世紀戰M：阿修羅計畫 | F33: =IF(A33="","", "https://www.ssbuy.tw/detail_giftcode/dist/giftcodes/" & IF(ISNUMBER(LEFT(A33,1)*1), "game-", "") & A33 & ".html") -> https://www.ssbuy.tw/detail_giftcode/dist/giftcodes/創世紀戰M：阿修羅計畫.html | H33: =IF(A33="","", "https://www.ssbuy.tw/detail_giftcode/dist/gamedetail/" & IF(ISNUMBER(LEFT(A33,1)*1), "game-", "") & A33 & ".html") -> https://www.ssbuy.tw/detail_giftcode/dist/gamedetail/創世紀戰M：阿修羅計畫.html | I33: 富饒廣闊的安塔利亞大陸，因戰爭爆發一切風雲變色，飽受戰爭欺凌， 王女伊歐林帶著王國騎士團，憑藉勇氣與智慧復國，對抗艱難命運。 面對強大武力的蓋席勒帝國，也絕不屈服！ | J33: 6350鑽石 | K33: 2551 | L33: 4400鑽石 | M33: 1980 | N33: 3200鑽石 | O33: 1323 | P33: 1850鑽石 | Q33: 786 | R33: 1250鑽石 | S33: 539 | T33: 900鑽石 | U33: 394 | V33: 310鑽石 | W33: 137 | X33: 60鑽石 | Y33: 40
A34: 最強宗師 | F34: =IF(A34="","", "https://www.ssbuy.tw/detail_giftcode/dist/giftcodes/" & IF(ISNUMBER(LEFT(A34,1)*1), "game-", "") & A34 & ".html") -> https://www.ssbuy.tw/detail_giftcode/dist/giftcodes/最強宗師.html | H34: =IF(A34="","", "https://www.ssbuy.tw/detail_giftcode/dist/gamedetail/" & IF(ISNUMBER(LEFT(A34,1)*1), "game-", "") & A34 & ".html") -> https://www.ssbuy.tw/detail_giftcode/dist/gamedetail/最強宗師.html | I34: 《最強宗師》是一款最強卡牌策略RPG，在這裡，每位角色都有獨特特質，不存在廢卡，所有資源都能無損傳承，讓你輕鬆成為最強宗師！躺平掛機也能生產材料，輕鬆實現戰力飆升。策略搭配、多樣玩法，帶你領略充滿熱血與智慧的宗門修煉之路！在這裡，人人都可以是主角，天選之人，唯我最強！ | J34: 99.99美金仙玉 | K34: 2551 | L34: 49.99美金仙玉 | M34: 1323 | N34: 29.99美金仙玉 | O34: 786 | P34: 19.99美金仙玉 | Q34: 539 | R34: 14.99美金仙玉 | S34: 394 | T34: 9.99美金仙玉 | U34: 267 | V34: 4.99美金仙玉 | W34: 137 | X34: 1.99美金仙玉 | Y34: 60 | Z34: 0.99美金仙玉 | AA34: 35
A35: 無期迷途 | F35: =IF(A35="","", "https://www.ssbuy.tw/detail_giftcode/dist/giftcodes/" & IF(ISNUMBER(LEFT(A35,1)*1), "game-", "") & A35 & ".html") -> https://www.ssbuy.tw/detail_giftcode/dist/giftcodes/無期迷途.html | H35: =IF(A35="","", "https://www.ssbuy.tw/detail_giftcode/dist/gamedetail/" & IF(ISNUMBER(LEFT(A35,1)*1), "game-", "") & A35 & ".html") -> https://www.ssbuy.tw/detail_giftcode/dist/gamedetail/無期迷途.html | I35: 《無期迷途》是款以混沌都市為主題的RPG即時策略攻防手遊。身為【米諾斯危機管理局】局長的你，將親手追蹤並收容擁有特殊力量的異能使者——禁閉者們。使用禁閉者的禁忌力量，揭開隱藏在這個世界的真相！ 「您好，新任的局長，我們一直都在等你。」這裡是米諾斯危機管理局，一座收容禁閉者的隱密場所。而您——令人尊敬的局長，將在此釋放其中最強大的禁閉者們。他們或舉止優雅，或性情乖張，或美艷狡猾；唯一的共同點他們都有不為人知的過去，以及超越常人的超凡之力。 局長，請盡情使用他們的力量，深入狄斯城的禁區，尋找讓世界異變的源頭，解開瘋狂恐怖謎團，去扭轉命運吧！ | J35: 6480晶源 | K35: 2360 | L35: 3280晶源 | M35: 1200 | N35: 1980晶源 | O35: 800 | P35: 980晶源 | Q35: 420 | R35: 300晶源 | S35: 137 | T35: 60晶源 | U35: 30
A36: 絕區零 | F36: =IF(A36="","", "https://www.ssbuy.tw/detail_giftcode/dist/giftcodes/" & IF(ISNUMBER(LEFT(A36,1)*1), "game-", "") & A36 & ".html") -> https://www.ssbuy.tw/detail_giftcode/dist/giftcodes/絕區零.html | H36: =IF(A36="","", "https://www.ssbuy.tw/detail_giftcode/dist/gamedetail/" & IF(ISNUMBER(LEFT(A36,1)*1), "game-", "") & A36 & ".html") -> https://www.ssbuy.tw/detail_giftcode/dist/gamedetail/絕區零.html | I36: 遊戲故事發生在被神秘災害「空洞」所侵襲的後世界末日世界中，主角是一位名為「繩匠」的角色，負責引導人們進入「空洞」並與怪物「以骸」戰鬥。 | J36: 6480菲林底片 | K36: 2520 | L36: 3280菲林底片 | M36: 1323 | N36: 1980菲林底片 | O36: 786 | P36: 980菲林底片 | Q36: 394 | R36: 300菲林底片 | S36: 137 | T36: 60菲林底片 | U36: 30 | V36: 繩網會員 | W36: 137 | X36: 成長計畫 | Y36: 270 | Z36: 典藏計畫 | AA36: 540
A37: 傳說對決 | F37: =IF(A37="","", "https://www.ssbuy.tw/detail_giftcode/dist/giftcodes/" & IF(ISNUMBER(LEFT(A37,1)*1), "game-", "") & A37 & ".html") -> https://www.ssbuy.tw/detail_giftcode/dist/giftcodes/傳說對決.html | H37: =IF(A37="","", "https://www.ssbuy.tw/detail_giftcode/dist/gamedetail/" & IF(ISNUMBER(LEFT(A37,1)*1), "game-", "") & A37 & ".html") -> https://www.ssbuy.tw/detail_giftcode/dist/gamedetail/傳說對決.html | I37: Garena 傳說對決是一款節奏快速、輕鬆又不失競技成分的MOBA 手遊，經典玩法加上獨特的輪盤指向施法的直覺操作模式，輕鬆競技於指掌之間！ | J37: 4110點券 | K37: 2660 | L37: 3692點券 | M37: 2350 | N37: 2943點券 | O37: 1890 | P37: 2047點券 | Q37: 1390 | R37: 1466點券 | S37: 970 | T37: 1092點券 | U37: 750 | V37: 728點券 | W37: 490 | X37: 364點券 | Y37: 250
A38: 楓之谷M | F38: =IF(A38="","", "https://www.ssbuy.tw/detail_giftcode/dist/giftcodes/" & IF(ISNUMBER(LEFT(A38,1)*1), "game-", "") & A38 & ".html") -> https://www.ssbuy.tw/detail_giftcode/dist/giftcodes/楓之谷M.html | H38: =IF(A38="","", "https://www.ssbuy.tw/detail_giftcode/dist/gamedetail/" & IF(ISNUMBER(LEFT(A38,1)*1), "game-", "") & A38 & ".html") -> https://www.ssbuy.tw/detail_giftcode/dist/gamedetail/楓之谷M.html | I38: 《楓之谷M》是一款由Nexon開發的免費大型多人線上角色扮演遊戲，是基於《楓之谷》的移動版。 遊戲中玩家可以扮演來自各地的角色，進行冒險、戰鬥、任務、以及和其他玩家互動。 | J38: 3290商品 | K38: 2551 | L38: 1690商品 | M38: 1390 | N38: 990商品 | O38: 786 | P38: 670商品 | Q38: 539 | R38: 330商品 | S38: 267 | T38: 170商品 | U38: 137 | V38: 33商品 | W38: 35
A39: 鳴潮 | F39: =IF(A39="","", "https://www.ssbuy.tw/detail_giftcode/dist/giftcodes/" & IF(ISNUMBER(LEFT(A39,1)*1), "game-", "") & A39 & ".html") -> https://www.ssbuy.tw/detail_giftcode/dist/giftcodes/鳴潮.html | H39: =IF(A39="","", "https://www.ssbuy.tw/detail_giftcode/dist/gamedetail/" & IF(ISNUMBER(LEFT(A39,1)*1), "game-", "") & A39 & ".html") -> https://www.ssbuy.tw/detail_giftcode/dist/gamedetail/鳴潮.html | I39: 《鳴潮》是一款末世題材的開放世界遊戲，具有高自由度且豐富的內容。 遊戲玩法包括攀爬、滑翔、採集等開放世界要素，還新增了「跑牆」的元素。 本作動作方面採用玩家能夠「閃避」和「彈刀」兩種招架方式。 | J39: 6480月相 | K39: 2320 | L39: 3280月相 | M39: 1323 | N39: 1980月相 | O39: 786 | P39: 980月相 | Q39: 394 | R39: 300月相 | S39: 137 | T39: 60月相 | U39: 30 | V39: 月相觀測卡 | W39: 137 | X39: 寰宇頻道 | Y39: 260 | Z39: 寰宇特約 | AA39: 520
A40: 劍與遠征：啟程 | F40: =IF(A40="","", "https://www.ssbuy.tw/detail_giftcode/dist/giftcodes/" & IF(ISNUMBER(LEFT(A40,1)*1), "game-", "") & A40 & ".html") -> https://www.ssbuy.tw/detail_giftcode/dist/giftcodes/劍與遠征：啟程.html | H40: =IF(A40="","", "https://www.ssbuy.tw/detail_giftcode/dist/gamedetail/" & IF(ISNUMBER(LEFT(A40,1)*1), "game-", "") & A40 & ".html") -> https://www.ssbuy.tw/detail_giftcode/dist/gamedetail/劍與遠征：啟程.html | I40: 《劍與遠征：啟程》是一款全球多平台的輕鬆放置大世界RPG遊戲，由放置始祖《劍與遠征》開發團隊所打造。 玩家將集結超過百位不同能力、各具魅力的英雄夥伴，與他們一起探索名為「伊索米亞」的廣闊大世界，並逐漸揭開其中秘辛 | J40: 3290商品 | K40: 2420 | L40: 1690商品 | M40: 1323 | N40: 990商品 | O40: 786 | P40: 670商品 | Q40: 539 | R40: 330商品 | S40: 267 | T40: 170商品 | U40: 137 | V40: 33商品 | W40: 35
...

Sheet gift_codes
A1: 遊戲名稱 | B1: 橫幅圖片 | C1: 橫幅圖片檔名 | D1: canonical_url | E1: 介紹 | F1: 兌換方式1 | G1: 兌換方式3 | H1: 兌換方式4 | I1: 兌換方式5 | J1: 兌換方式6 | K1: 禮包碼1 | L1: 內容物1 | M1: 禮包碼2 | N1: 內容物2 | O1: 禮包碼3 | P1: 內容物3 | Q1: 禮包碼4 | R1: 內容物4 | S1: 禮包碼5 | T1: 內容物5 | U1: 禮包碼6 | V1: 內容物6 | W1: 禮包碼7 | X1: 內容物7 | Y1: 禮包碼8 | Z1: 內容物8 | AA1: 禮包碼9 | AB1: 內容物9 | AC1: 禮包碼10 | AD1: 內容物10 | AE1: 禮包碼11 | AF1: 內容物11 | AG1: 禮包碼12 | AH1: 內容物12 | AI1: 禮包碼13 | AJ1: 內容物13 | AK1: 禮包碼14 | AL1: 內容物14 | AM1: 禮包碼15 | AN1: 內容物15 | AO1: 禮包碼16 | AP1: 內容物16 | AQ1: 禮包碼17 | AR1: 內容物17 | AS1: 禮包碼18 | AT1: 內容物18 | AU1: 禮包碼19 | AV1: 內容物19 | AW1: 禮包碼20 | AX1: 內容物20 | AY1: 禮包碼21 | AZ1: 內容物21 | BA1: 禮包碼22 | BB1: 內容物22 | BC1: 禮包碼23 | BD1: 內容物23 | BE1: 禮包碼24 | BF1: 內容物24 | BG1: 禮包碼25 | BH1: 內容物25 | BI1: 禮包碼26 | BJ1: 內容物26 | BK1: 禮包碼27 | BL1: 內容物27 | BM1: 禮包碼28 | BN1: 內容物28 | BO1: 禮包碼29 | BP1: 內容物29 | BQ1: 禮包碼30 | BR1: 內容物30
A2: 巔峰極速 | B2: ="giftcodesbanner/" & A2 & "-bar.jpg" -> giftcodesbanner/巔峰極速-bar.jpg | D2: =IF(A2="","", "https://www.ssbuy.tw/detail_giftcode/dist/giftcodes/" & IF(ISNUMBER(LEFT(A2,1)*1), "game-", "") & A2 & ".html") -> https://www.ssbuy.tw/detail_giftcode/dist/giftcodes/巔峰極速.html | E2: 《巔峰極速》是與Codemasters®深度合作, 3A級巔峰品質擬真競速遊戲。 玩家可以自由收集、改裝超過100款正版授權的豪華車輛，馳騁在全世界的街道與專業賽道上，感受極致光影與真實轟鳴聲帶來的沉浸體驗，更擁有豐富的競速玩法，立即加入與其他玩家進行即時競速對決，突破賽車的速度極限！ | F2: 進入主畫面，點選個人頭像 | G2: 進入設定（齒輪） | H2: 輸入禮包碼 → 確認兌換 | K2: 10000racers | L2: 2025商城元寶鑽石禮包 | M2: VIP777 | N2: 2025商城元寶鑽石禮包 | O2: VIP888 | P2: 2025商城元寶鑽石禮包 | Q2: KINGO1019 | R2: 2025商城元寶鑽石禮包 | S2: BEBE888 | T2: 2025商城元寶鑽石禮包 | U2: TEAMRACE666 | V2: 2025商城元寶鑽石禮包 | W2: RACING777 | X2: 2025商城元寶鑽石禮包 | Y2: POST00 | Z2: 2025商城元寶鑽石禮包 | AA2: RACING888 | AB2: 2025商城元寶鑽石禮包 | AC2: NEAL888 | AD2: 2025商城元寶鑽石禮包 | AE2: RKUI666 | AF2: 2025商城元寶鑽石禮包 | AG2: LETSGO168 | AH2: 2025商城元寶鑽石禮包 | AI2: DRIVER666 | AJ2: 2025商城元寶鑽石禮包 | AK2: MASTER777 | AL2: 2025商城元寶鑽石禮包 | AM2: AHHINS | AN2: 2025商城元寶鑽石禮包 | AO2: RACING666 | AP2: 2025商城元寶鑽石禮包 | AQ2: WINWIN888 | AR2: 2025商城元寶鑽石禮包 | AS2: GOGORACING | AT2: 2025商城元寶鑽石禮包 | AU2: GG1019 | AV2: 2025商城元寶鑽石禮包
A3: 原神 | B3: ="giftcodesbanner/" & A3 & "-bar.jpg" -> giftcodesbanner/原神-bar.jpg | D3: =IF(A3="","", "https://www.ssbuy.tw/detail_giftcode/dist/giftcodes/" & IF(ISNUMBER(LEFT(A3,1)*1), "game-", "") & A3 & ".html") -> https://www.ssbuy.tw/detail_giftcode/dist/giftcodes/原神.html | E3: 原神，啟動! | F3: 進入主畫面，點選個人頭像 | G3: 進入設定（齒輪） | H3: 輸入禮包碼 → 確認兌換 | K3: GS57YTSNLJ | L3: 原神素材兌換專用 | M3: LWKC638ULB16 | N3: 摩拉 x10,000、冒險家的經驗 x10、精鍛用雜礦 x5、香嫩椒椒雞 x5、乾炒魚河 x5 | O3: ZT5RJ4AX4WYV | P3: 原石 x60、冒險家的經驗 x5 | Q3: GenshinGIFT | R3: 原石 x50、大英雄的經驗 x3
A4: 極速快感 | B4: ="giftcodesbanner/" & A4 & "-bar.jpg" -> giftcodesbanner/極速快感-bar.jpg | D4: =IF(A4="","", "https://www.ssbuy.tw/detail_giftcode/dist/giftcodes/" & IF(ISNUMBER(LEFT(A4,1)*1), "game-", "") & A4 & ".html") -> https://www.ssbuy.tw/detail_giftcode/dist/giftcodes/極速快感.html | F4: 進入主畫面，點選個人頭像 | G4: 進入設定（齒輪） | H4: 輸入禮包碼 → 確認兌換 | K4: 極速快感集結666 | L4: 100鑽石、500熱彎幣 | M4: 極速快感沖刺測試 | N4: 50鑽石、300熱彎幣 | O4: NFSM7EUV49 | P4: 2025商城元寶鑽石禮包 | Q4: NEEDFORSPEEDNOX | R4: 2025商城元寶鑽石禮包
A5: 俠客傳說：小小英雄 | B5: ="giftcodesbanner/" & A5 & "-bar.jpg" -> giftcodesbanner/俠客傳說：小小英雄-bar.jpg | D5: =IF(A5="","", "https://www.ssbuy.tw/detail_giftcode/dist/giftcodes/" & IF(ISNUMBER(LEFT(A5,1)*1), "game-", "") & A5 & ".html") -> https://www.ssbuy.tw/detail_giftcode/dist/giftcodes/俠客傳說：小小英雄.html | E5: 有你的地方，就有江湖。 | F5: 進入主畫面，點選個人頭像 | G5: 進入設定（齒輪） | H5: 輸入禮包碼 → 確認兌換 | K5: sshero | L5: 2025商城元寶鑽石禮包 | M5: sshero66 | N5: 2025商城元寶鑽石禮包 | O5: tiger666 | P5: 2025商城元寶鑽石禮包 | Q5: tiger777 | R5: 2025商城元寶鑽石禮包 | S5: iu216yrtm4bn | T5: 2025商城元寶鑽石禮包 | U5: 4d9xnyukxwsn | V5: 2025商城元寶鑽石禮包 | W5: x4ixkxaqglaq | X5: 2025商城元寶鑽石禮包 | Y5: zbetdmodzxpj | Z5: 2025商城元寶鑽石禮包 | AA5: fp4rg7gq1g3a | AB5: 2025商城元寶鑽石禮包 | AC5: ox3olzfmkl1d | AD5: 2025商城元寶鑽石禮包 | AE5: ivqjvbqs4r7r | AF5: 2025商城元寶鑽石禮包 | AG5: bx523bo9c678 | AH5: 2025商城元寶鑽石禮包 | AI5: vdpppx11t12n | AJ5: 2025商城元寶鑽石禮包
A6: 逆水寒 | B6: ="giftcodesbanner/" & A6 & "-bar.jpg" -> giftcodesbanner/逆水寒-bar.jpg | D6: =IF(A6="","", "https://www.ssbuy.tw/detail_giftcode/dist/giftcodes/" & IF(ISNUMBER(LEFT(A6,1)*1), "game-", "") & A6 & ".html") -> https://www.ssbuy.tw/detail_giftcode/dist/giftcodes/逆水寒.html | E6: 新武俠大世界冒險RPG《俠客傳說：小小英雄》 | F6: 進入主畫面，點選個人頭像 | G6: 進入設定（齒輪） | H6: 輸入禮包碼 → 確認兌換 | K6: MMOKING | L6: 66綁定紋玉、28,888交子
A7: RO仙境傳說：一定要可愛 | B7: ="giftcodesbanner/" & A7 & "-bar.jpg" -> giftcodesbanner/RO仙境傳說：一定要可愛-bar.jpg | D7: =IF(A7="","", "https://www.ssbuy.tw/detail_giftcode/dist/giftcodes/" & IF(ISNUMBER(LEFT(A7,1)*1), "game-", "") & A7 & ".html") -> https://www.ssbuy.tw/detail_giftcode/dist/giftcodes/RO仙境傳說：一定要可愛.html | E7: 可不可愛？我們說了算！ | F7: 進入主畫面，點選個人頭像 | G7: 進入設定（齒輪） | H7: 輸入禮包碼 → 確認兌換 | K7: BahamutNO1 | L7: 懸賞通緝掃蕩權 × 4 | M7: fanpage3000 | N7: ZENY*30,000 | O7: NOVICE01 | P7: 地城入場補充卷*1 | Q7: SWORDSMAN02 | R7: 地城入場補充卷*1 | S7: BahamutNO1 | T7: 懸賞通緝掃蕩權* 4 | U7: ARCHER03 | V7: 十字搞*2 | W7: ACOLYTE04 | X7: 蜂蜜*5
A8: RO新世代 | B8: ="giftcodesbanner/" & A8 & "-bar.jpg" -> giftcodesbanner/RO新世代-bar.jpg | D8: =IF(A8="","", "https://www.ssbuy.tw/detail_giftcode/dist/giftcodes/" & IF(ISNUMBER(LEFT(A8,1)*1), "game-", "") & A8 & ".html") -> https://www.ssbuy.tw/detail_giftcode/dist/giftcodes/RO新世代.html | E8: 官方正版RO最新作「RO仙境傳説：新世代的誕生」，煥新啓航！不刪檔公測開啟！ | F8: 進入主畫面，點選個人頭像 | G8: 進入設定（齒輪） | H8: 輸入禮包碼 → 確認兌換 | K8: pfyloveroxictop4 | L8: 2025商城元寶鑽石禮包 | M8: ROXIC666J | N8: 2025商城元寶鑽石禮包 | O8: ROXIC636J | P8: 2025商城元寶鑽石禮包 | Q8: ROXIC973J | R8: 2025商城元寶鑽石禮包 | S8: ROXIC562J | T8: 2025商城元寶鑽石禮包 | U8: FPCPAJIE2624 | V8: 2025商城元寶鑽石禮包
A9: 上古：龍神覺醒 | B9: ="giftcodesbanner/" & A9 & "-bar.jpg" -> giftcodesbanner/上古：龍神覺醒-bar.jpg | D9: =IF(A9="","", "https://www.ssbuy.tw/detail_giftcode/dist/giftcodes/" & IF(ISNUMBER(LEFT(A9,1)*1), "game-", "") & A9 & ".html") -> https://www.ssbuy.tw/detail_giftcode/dist/giftcodes/上古：龍神覺醒.html | E9: 首款龍主題MMO鉅作！ | F9: 進入主畫面，點選個人頭像 | G9: 進入設定（齒輪） | H9: 輸入禮包碼 → 確認兌換 | K9: DG666 | L9: 2025商城元寶鑽石禮包 | M9: DG777 | N9: 2025商城元寶鑽石禮包 | O9: DG888 | P9: 2025商城元寶鑽石禮包 | Q9: VIP666 | R9: 2025商城元寶鑽石禮包 | S9: VIP777 | T9: 2025商城元寶鑽石禮包 | U9: VIP888 | V9: 2025商城元寶鑽石禮包 | W9: SVIP666 | X9: 2025商城元寶鑽石禮包 | Y9: SVIP777 | Z9: 2025商城元寶鑽石禮包 | AA9: SVIP888 | AB9: 2025商城元寶鑽石禮包 | AC9: EVE209 | AD9: 2025商城元寶鑽石禮包 | AE9: NEW2024 | AF9: 2025商城元寶鑽石禮包 | AG9: LF2233 | AH9: 2025商城元寶鑽石禮包
A10: 小艦艦超勇 | B10: ="giftcodesbanner/" & A10 & "-bar.jpg" -> giftcodesbanner/小艦艦超勇-bar.jpg | D10: =IF(A10="","", "https://www.ssbuy.tw/detail_giftcode/dist/giftcodes/" & IF(ISNUMBER(LEFT(A10,1)*1), "game-", "") & A10 & ".html") -> https://www.ssbuy.tw/detail_giftcode/dist/giftcodes/小艦艦超勇.html | E10: 無止境的武器升級，打造你的最強艦隊！ | F10: 進入主畫面，點選個人頭像 | G10: 進入設定（齒輪） | H10: 輸入禮包碼 → 確認兌換 | K10: OUTLANDER777 | L10: 2025商城元寶鑽石禮包 | M10: ABBY01011 | N10: 2025商城元寶鑽石禮包 | O10: MIMI01021 | P10: 2025商城元寶鑽石禮包 | Q10: HIGHSEASHEROGO | R10: 2025商城元寶鑽石禮包 | S10: HAPPYHSH777 | T10: 2025商城元寶鑽石禮包 | U10: VIP777 | V10: 2025商城元寶鑽石禮包 | W10: VIP888 | X10: 2025商城元寶鑽石禮包 | Y10: HSHLAUNCH0109 | Z10: 2025商城元寶鑽石禮包
A11: 天使軍團 | B11: ="giftcodesbanner/" & A11 & "-bar.jpg" -> giftcodesbanner/天使軍團-bar.jpg | D11: =IF(A11="","", "https://www.ssbuy.tw/detail_giftcode/dist/giftcodes/" & IF(ISNUMBER(LEFT(A11,1)*1), "game-", "") & A11 & ".html") -> https://www.ssbuy.tw/detail_giftcode/dist/giftcodes/天使軍團.html | E11: 天使軍團是最新推出的3D天使銀河冒險RPG手遊。 希拉星系，深邃而瑰麗……這裡曾存在著古老時期的文明。 | F11: 進入主畫面，點選個人頭像 | G11: 進入設定（齒輪） | H11: 輸入禮包碼 → 確認兌換 | K11: DscdRetrom43zw | L11: 2025商城元寶鑽石禮包 | M11: Mkjptfjlny8j31 | N11: 2025商城元寶鑽石禮包 | O11: ALFacebook | P11: 2025商城元寶鑽石禮包
A12: 天堂W | B12: ="giftcodesbanner/" & A12 & "-bar.jpg" -> giftcodesbanner/天堂W-bar.jpg | D12: =IF(A12="","", "https://www.ssbuy.tw/detail_giftcode/dist/giftcodes/" & IF(ISNUMBER(LEFT(A12,1)*1), "game-", "") & A12 & ".html") -> https://www.ssbuy.tw/detail_giftcode/dist/giftcodes/天堂W.html | E12: 《天堂W》是繼承PC MMORPG天堂正統性的跨平台遊戲，全球單一版本服務，即時AI翻譯；Full 3D畫面和斜45度視角開發的暗黑奇幻世界；將天堂的核心內容戰鬥社群延伸到世界。 | F12: 進入主畫面，點選個人頭像 | G12: 進入設定（齒輪） | H12: 輸入禮包碼 → 確認兌換 | K12: HOTNEWYEARADEN24 | L12: 2025商城元寶鑽石禮包 | M12: BLUEDRAGONW | N12: 2025商城元寶鑽石禮包
A13: 少女前線2：追放 | B13: ="giftcodesbanner/" & A13 & "-bar.jpg" -> giftcodesbanner/少女前線2：追放-bar.jpg | D13: =IF(A13="","", "https://www.ssbuy.tw/detail_giftcode/dist/giftcodes/" & IF(ISNUMBER(LEFT(A13,1)*1), "game-", "") & A13 & ".html") -> https://www.ssbuy.tw/detail_giftcode/dist/giftcodes/少女前線2：追放.html | E13: 講述了指揮官與格里芬之間無法調和的理念衝突，導致指揮官選擇自我流放，成為賞金獵人。 | F13: 進入主畫面，點選個人頭像 | G13: 進入設定（齒輪） | H13: 輸入禮包碼 → 確認兌換 | K13: ULLRID1205 | L13: 戰場報告*5000、解析圖紙*5000 | M13: SUOMI1205 | N13: 戰場報告*5000、解析圖紙*5000 | O13: ELMO1205 | P13: 坍塌晶條*150、薩狄斯金*5000 | Q13: EXILIUMDC | R13: 戰場報告*5000、解析圖紙*5000 | S13: GLASSISLE | T13: 2025商城元寶鑽石禮包 | U13: ELMOLIVE | V13: 坍塌晶條*50、戰場報告*5000、解析圖紙*5000 | W13: OMNGKTWN | X13: 坍塌晶條*150、薩狄斯金*3000、接入密鑰*2 | Y13: GFL2LAUNCH | Z13: 接入密鑰*1、大容量記憶體*2
A14: 幻獸傳說Ｍ | B14: ="giftcodesbanner/" & A14 & "-bar.jpg" -> giftcodesbanner/幻獸傳說Ｍ-bar.jpg | D14: =IF(A14="","", "https://www.ssbuy.tw/detail_giftcode/dist/giftcodes/" & IF(ISNUMBER(LEFT(A14,1)*1), "game-", "") & A14 & ".html") -> https://www.ssbuy.tw/detail_giftcode/dist/giftcodes/幻獸傳說Ｍ.html | E14: 2025年萬眾期待的幻獸手遊來啦！異世界捉獸育獸RPG《幻獸傳說M》現已上市！豆花蔡黃汝可愛代言，演繹疾海兔！ | F14: 進入主畫面，點選個人頭像 | G14: 進入設定（齒輪） | H14: 輸入禮包碼 → 確認兌換 | K14: FAFA666 | L14: 2025商城元寶鑽石禮包 | M14: FAFA777 | N14: 2025商城元寶鑽石禮包 | O14: FAFA888 | P14: 2025商城元寶鑽石禮包 | Q14: SSSVIP333 | R14: 2025商城元寶鑽石禮包 | S14: SSSVIP444 | T14: 2025商城元寶鑽石禮包 | U14: SSSVIP555 | V14: 2025商城元寶鑽石禮包 | W14: VIP555 | X14: 2025商城元寶鑽石禮包 | Y14: VIP666 | Z14: 2025商城元寶鑽石禮包 | AA14: VIP777 | AB14: 2025商城元寶鑽石禮包 | AC14: VIP888 | AD14: 2025商城元寶鑽石禮包 | AE14: VIP999 | AF14: 2025商城元寶鑽石禮包 | AG14: INSTALL | AH14: 2025商城元寶鑽石禮包
A15: 未定事件簿 | B15: ="giftcodesbanner/" & A15 & "-bar.jpg" -> giftcodesbanner/未定事件簿-bar.jpg | D15: =IF(A15="","", "https://www.ssbuy.tw/detail_giftcode/dist/giftcodes/" & IF(ISNUMBER(LEFT(A15,1)*1), "game-", "") & A15 & ".html") -> https://www.ssbuy.tw/detail_giftcode/dist/giftcodes/未定事件簿.html | E15: 當正義與邪惡的界定越來越模糊，妳手中的天平將會傾向何方？一場戀愛與推理的冒險，此刻，邀妳共赴。 | F15: 進入主畫面，點選個人頭像 | G15: 進入設定（齒輪） | H15: 輸入禮包碼 → 確認兌換 | K15: HAPPY38WOMENSDAY | L15: 未名晶片*60+未名幣*3800+法理之諭III*8 | M15: 520FALLINLOVE | N15: 未名晶片×100+友誼徽章×520+未名幣×13140 | O15: SUMMERGIFT | P15: 未名晶片×60+未名幣×10000+能量飲料普通裝×1 | Q15: DRAGONBOAT | R15: 未名晶片×60+法理之諭III×20 | S15: HappyDragonBoat2025 | T15: 未名晶片×60、未名幣 ×5500、能量飲料普通裝 ×1
A16: 永恆靈魂 | B16: ="giftcodesbanner/" & A16 & "-bar.jpg" -> giftcodesbanner/永恆靈魂-bar.jpg | D16: =IF(A16="","", "https://www.ssbuy.tw/detail_giftcode/dist/giftcodes/" & IF(ISNUMBER(LEFT(A16,1)*1), "game-", "") & A16 & ".html") -> https://www.ssbuy.tw/detail_giftcode/dist/giftcodes/永恆靈魂.html | E16: 末日的今天，精靈們等候您的指示…救援者，帶領著她們的靈魂活下去吧。 | F16: 進入主畫面，點選個人頭像 | G16: 進入設定（齒輪） | H16: 輸入禮包碼 → 確認兌換 | K16: 2Qgift0325 | L16: 1,000個永恆石
A17: 守住呀主公 | B17: ="giftcodesbanner/" & A17 & "-bar.jpg" -> giftcodesbanner/守住呀主公-bar.jpg | D17: =IF(A17="","", "https://www.ssbuy.tw/detail_giftcode/dist/giftcodes/" & IF(ISNUMBER(LEFT(A17,1)*1), "game-", "") & A17 & ".html") -> https://www.ssbuy.tw/detail_giftcode/dist/giftcodes/守住呀主公.html | E17: 喜歡策略塔防、鍾愛三國名將的你，絕對不容錯過這款高畫質3D塔防力作！豐富的塔防玩法、酷炫的技能特效，讓你盡享爽快的遊戲體驗。 | F17: 進入主畫面，點選個人頭像 | G17: 進入設定（齒輪） | H17: 輸入禮包碼 → 確認兌換 | K17: VIP666 | L17: 2025商城元寶鑽石禮包 | M17: VIP888 | N17: 2025商城元寶鑽石禮包 | O17: WEEKGIFT | P17: 2025商城元寶鑽石禮包 | Q17: KH26UB56P | R17: 2025商城元寶鑽石禮包 | S17: UYJH658YY | T17: 2025商城元寶鑽石禮包 | U17: VIP6699 | V17: 2025商城元寶鑽石禮包 | W17: NOVGIHT | X17: 2025商城元寶鑽石禮包
A18: 吟遊戰記 | B18: ="giftcodesbanner/" & A18 & "-bar.jpg" -> giftcodesbanner/吟遊戰記-bar.jpg | D18: =IF(A18="","", "https://www.ssbuy.tw/detail_giftcode/dist/giftcodes/" & IF(ISNUMBER(LEFT(A18,1)*1), "game-", "") & A18 & ".html") -> https://www.ssbuy.tw/detail_giftcode/dist/giftcodes/吟遊戰記.html | E18: 新感覺放置型勇者冒險RPG，登入即可獲得免費9999連抽！輕鬆休閒的冒險，來一場解放雙手的戰鬥吧！ | F18: 進入主畫面，點選個人頭像 | G18: 進入設定（齒輪） | H18: 輸入禮包碼 → 確認兌換 | K18: VIP666 | L18: 2025商城元寶鑽石禮包 | M18: VIP777 | N18: 2025商城元寶鑽石禮包 | O18: VIP888 | P18: 2025商城元寶鑽石禮包 | Q18: VIP999 | R18: 2025商城元寶鑽石禮包
A19: 我獨自升級：ARISE | B19: ="giftcodesbanner/" & A19 & "-bar.jpg" -> giftcodesbanner/我獨自升級：ARISE-bar.jpg | D19: =IF(A19="","", "https://www.ssbuy.tw/detail_giftcode/dist/giftcodes/" & IF(ISNUMBER(LEFT(A19,1)*1), "game-", "") & A19 & ".html") -> https://www.ssbuy.tw/detail_giftcode/dist/giftcodes/我獨自升級：ARISE.html | E19: 德國最強的獵人，也是世界獵人排名第12名的S級「萊納德．尼爾曼」已加入完成！ | F19: 進入主畫面，點選個人頭像 | G19: 進入設定（齒輪） | H19: 輸入禮包碼 → 確認兌換 | K19: SLALIVESTREAM | L19: 2025商城元寶鑽石禮包 | M19: JULYUPDATELIVE | N19: 2025商城元寶鑽石禮包 | O19: SEEYOUSOON | P19: 2025商城元寶鑽石禮包 | Q19: SURPRISEGIFT | R19: 2025商城元寶鑽石禮包 | S19: THXSLVARISETHX | T19: 2025商城元寶鑽石禮包 | U19: WORLD1STLEVELUP | V19: 2025商城元寶鑽石禮包 | W19: SOLOLEVELING2025商城元寶鑽石禮包0508 | X19: 2025商城元寶鑽石禮包 | Y19: STAYSHARP | Z19: 2025商城元寶鑽石禮包
A20: 命運聖契：少女的羈絆 | B20: ="giftcodesbanner/" & A20 & "-bar.jpg" -> giftcodesbanner/命運聖契：少女的羈絆-bar.jpg | D20: =IF(A20="","", "https://www.ssbuy.tw/detail_giftcode/dist/giftcodes/" & IF(ISNUMBER(LEFT(A20,1)*1), "game-", "") & A20 & ".html") -> https://www.ssbuy.tw/detail_giftcode/dist/giftcodes/命運聖契：少女的羈絆.html | E20: 2025首款命運少女輕放置RPG手遊《命運聖契：少女的羈絆》霜糖奇典活动開啟！登錄可得自選SSR、限定頭像框及海量高價值虛寶。 | F20: 進入主畫面，點選個人頭像 | G20: 進入設定（齒輪） | H20: 輸入禮包碼 → 確認兌換 | K20: FEEL666 | L20: 2025商城元寶鑽石禮包 | M20: PEACH520 | N20: 2025商城元寶鑽石禮包 | O20: SEX000 | P20: 2025商城元寶鑽石禮包 | Q20: SEX666 | R20: 2025商城元寶鑽石禮包 | S20: SEX777 | T20: 2025商城元寶鑽石禮包 | U20: SEX888 | V20: 2025商城元寶鑽石禮包 | W20: SEX999 | X20: 2025商城元寶鑽石禮包 | Y20: FEEL001 | Z20: 2025商城元寶鑽石禮包 | AA20: FEEL003 | AB20: 2025商城元寶鑽石禮包 | AC20: FEEL888 | AD20: 2025商城元寶鑽石禮包 | AE20: FEEL999 | AF20: 2025商城元寶鑽石禮包
A21: 放置軍團 | B21: ="giftcodesbanner/" & A21 & "-bar.jpg" -> giftcodesbanner/放置軍團-bar.jpg | D21: =IF(A21="","", "https://www.ssbuy.tw/detail_giftcode/dist/giftcodes/" & IF(ISNUMBER(LEFT(A21,1)*1), "game-", "") & A21 & ".html") -> https://www.ssbuy.tw/detail_giftcode/dist/giftcodes/放置軍團.html | E21: 我們敬愛的魔王大人在與人類的決戰中，因為死亡騎士臨陣倒戈，被人類打碎成了渣渣。我們三個忠心耿耿的小鬼抬著魔王的靈魂碎片，躲進了一座廢棄的地下城。在這裡我們要重新建立地下城，儲備物資，集結軍團！ | F21: 進入主畫面，點選個人頭像 | G21: 進入設定（齒輪） | H21: 輸入禮包碼 → 確認兌換 | K21: 放置军团666 | L21: 氪晶*200 | M21: FZJT666 | N21: 魔晶*10000 | O21: 可靠的布道者 | P21: 氪晶*500 | Q21: 头秃古卜林们 | R21: 魔晶*20000 | S21: 我会回来的啊 | T21: 契约筹码*2
A22: 明日方舟 | B22: ="giftcodesbanner/" & A22 & "-bar.jpg" -> giftcodesbanner/明日方舟-bar.jpg | D22: =IF(A22="","", "https://www.ssbuy.tw/detail_giftcode/dist/giftcodes/" & IF(ISNUMBER(LEFT(A22,1)*1), "game-", "") & A22 & ".html") -> https://www.ssbuy.tw/detail_giftcode/dist/giftcodes/明日方舟.html | E22: 迷宮裡……竟然存在這樣的地方？準備好刀劍和法杖，也別忘了鍋、鏟和調味料！準備好了嗎，我們要開動了喔！ | F22: 進入主畫面，點選個人頭像 | G22: 進入設定（齒輪） | H22: 輸入禮包碼 → 確認兌換 | K22: 5VVK6LN5BM3GLFA6 | L22: 理智*60、中級作戰紀錄*20、龍門幣*20000
A23: 屍鬼三國 | B23: ="giftcodesbanner/" & A23 & "-bar.jpg" -> giftcodesbanner/屍鬼三國-bar.jpg | D23: =IF(A23="","", "https://www.ssbuy.tw/detail_giftcode/dist/giftcodes/" & IF(ISNUMBER(LEFT(A23,1)*1), "game-", "") & A23 & ".html") -> https://www.ssbuy.tw/detail_giftcode/dist/giftcodes/屍鬼三國.html | E23: 獨一款屍鬼化的三國卡牌手遊上市啦！新世代三國卡牌鉅作，融合了ARPG的開放世界設計，你可以在屍鬼橫行的三國亂世中自由探索。 | F23: 進入主畫面，點選個人頭像 | G23: 進入設定（齒輪） | H23: 輸入禮包碼 → 確認兌換 | K23: VIP666 | L23: 2025商城元寶鑽石禮包 | M23: VIP777 | N23: 2025商城元寶鑽石禮包 | O23: VIP888 | P23: 2025商城元寶鑽石禮包 | Q23: SG444 | R23: 2025商城元寶鑽石禮包 | S23: SG666 | T23: 2025商城元寶鑽石禮包 | U23: SG888 | V23: 2025商城元寶鑽石禮包 | W23: SSSVIP | X23: 2025商城元寶鑽石禮包 | Y23: 開服大吉 | Z23: 2025商城元寶鑽石禮包 | AA23: 屍鬼關羽 | AB23: 2025商城元寶鑽石禮包 | AC23: EGAMEPAY | AD23: 2025商城元寶鑽石禮包
A24: 星鏈計畫：未來少女 | B24: ="giftcodesbanner/" & A24 & "-bar.jpg" -> giftcodesbanner/星鏈計畫：未來少女-bar.jpg | D24: =IF(A24="","", "https://www.ssbuy.tw/detail_giftcode/dist/giftcodes/" & IF(ISNUMBER(LEFT(A24,1)*1), "game-", "") & A24 & ".html") -> https://www.ssbuy.tw/detail_giftcode/dist/giftcodes/星鏈計畫：未來少女.html | E24: 在無盡的絕望中，為少女們構築希望藍圖！ | F24: 進入主畫面，點選個人頭像 | G24: 進入設定（齒輪） | H24: 輸入禮包碼 → 確認兌換 | K24: TGS24STARSEED | L24: 10張綠券 | M24: CHASINGLEINSTARS | N24: 5張綠券 | O24: STARSEEDFREEGIFT | P24: 200星際比特 | Q24: GET5STARSEEDGIRLS | R24: 5張綠券 | S24: SIAXFREYJA | T24: 5張金券 | U24: 2024STARMAS | V24: 5張綠券
A25: 英雄之王 | B25: ="giftcodesbanner/" & A25 & "-bar.jpg" -> giftcodesbanner/英雄之王-bar.jpg | D25: =IF(A25="","", "https://www.ssbuy.tw/detail_giftcode/dist/giftcodes/" & IF(ISNUMBER(LEFT(A25,1)*1), "game-", "") & A25 & ".html") -> https://www.ssbuy.tw/detail_giftcode/dist/giftcodes/英雄之王.html | E25: 除了我們分享的遊戲畫面、影片和其他細節之外，我還想讓大家了解我們對遊戲的期望與願景。 我們希望能藉由《英雄之王》捕捉遊戲的本質。 | F25: 進入主畫面，點選個人頭像 | G25: 進入設定（齒輪） | H25: 輸入禮包碼 → 確認兌換 | K25: FORUM4U | L25: 2025商城元寶鑽石禮包 | M25: THXKAKAO | N25: 2025商城元寶鑽石禮包 | O25: WELCOMELOH | P25: 2025商城元寶鑽石禮包 | Q25: GOOGLEBEST | R25: 2025商城元寶鑽石禮包 | S25: LOHFORTUNE | T25: 2025商城元寶鑽石禮包 | U25: JPGOOGLE1 | V25: 2025商城元寶鑽石禮包 | W25: LEVELUPUP | X25: 2025商城元寶鑽石禮包 | Y25: GOOGLEFAME | Z25: 2025商城元寶鑽石禮包 | AA25: THANKSLORD | AB25: 2025商城元寶鑽石禮包
A26: 英雄聯盟 | B26: ="giftcodesbanner/" & A26 & "-bar.jpg" -> giftcodesbanner/英雄聯盟-bar.jpg | D26: =IF(A26="","", "https://www.ssbuy.tw/detail_giftcode/dist/giftcodes/" & IF(ISNUMBER(LEFT(A26,1)*1), "game-", "") & A26 & ".html") -> https://www.ssbuy.tw/detail_giftcode/dist/giftcodes/英雄聯盟.html | F26: 進入主畫面，點選個人頭像 | G26: 進入設定（齒輪） | H26: 輸入禮包碼 → 確認兌換 | K26: G9TGAS2024 | L26: 英雄六選一 + 流星頭像 | M26: G9FB888 | N26: 3000金幣
A27: 恐龍突變 | B27: ="giftcodesbanner/" & A27 & "-bar.jpg" -> giftcodesbanner/恐龍突變-bar.jpg | D27: =IF(A27="","", "https://www.ssbuy.tw/detail_giftcode/dist/giftcodes/" & IF(ISNUMBER(LEFT(A27,1)*1), "game-", "") & A27 & ".html") -> https://www.ssbuy.tw/detail_giftcode/dist/giftcodes/恐龍突變.html | E27: » 配對以產生受精卵: 進行戰略性交配以創造更強大的恐龍。» 點擊孵化無限的蛋: 不斷擴展你的恐龍收藏。 | F27: 進入主畫面，點選個人頭像 | G27: 進入設定（齒輪） | H27: 輸入禮包碼 → 確認兌換
A28: 神域 | B28: ="giftcodesbanner/" & A28 & "-bar.jpg" -> giftcodesbanner/神域-bar.jpg | D28: =IF(A28="","", "https://www.ssbuy.tw/detail_giftcode/dist/giftcodes/" & IF(ISNUMBER(LEFT(A28,1)*1), "game-", "") & A28 & ".html") -> https://www.ssbuy.tw/detail_giftcode/dist/giftcodes/神域.html | E28: 對抗邪惡勢力，策略過人的您並非孤軍奮戰，來自世界各地且為數眾多的神話英雄，正等待您的召喚！透過遊戲掛機得到的寶石、材料及各種資源，一支強而有力且技能靈活的自訂專屬軍團，就在您的股掌之間！ | F28: 進入主畫面，點選個人頭像 | G28: 進入設定（齒輪） | H28: 輸入禮包碼 → 確認兌換 | K28: MH8888 | L28: 永久兌換碼 | M28: MH7777 | N28: 永久兌換碼
A29: 崩壞：星穹鐵道 | B29: ="giftcodesbanner/" & A29 & "-bar.jpg" -> giftcodesbanner/崩壞：星穹鐵道-bar.jpg | D29: =IF(A29="","", "https://www.ssbuy.tw/detail_giftcode/dist/giftcodes/" & IF(ISNUMBER(LEFT(A29,1)*1), "game-", "") & A29 & ".html") -> https://www.ssbuy.tw/detail_giftcode/dist/giftcodes/崩壞：星穹鐵道.html | E29: 這片銀河中有名為「星神」的存在，祂們造就現實，抹消星辰，在無數「世界」中留下祂們的痕跡。你——一名特殊的旅客，將偕同繼承「開拓」意志的同伴們，乘坐星穹列車穿越銀河，沿著某位「星神」曾經所行之途前進。你將由此探索新的文明、結識新的夥伴、在無數光怪陸離的「世界」之間展開新的冒險。所有你想知道的，都將在群星中找到解答。 那麼，準備好開始這段「開拓」之旅了嗎？ | F29: 進入主畫面，點選個人頭像 | G29: 進入設定（齒輪） | H29: 輸入禮包碼 → 確認兌換 | K29: WAJ7CVBC4SG3 | L29: 星瓊x50、信用點x10k
A30: 救世者之樹：新世界 | B30: ="giftcodesbanner/" & A30 & "-bar.jpg" -> giftcodesbanner/救世者之樹：新世界-bar.jpg | D30: =IF(A30="","", "https://www.ssbuy.tw/detail_giftcode/dist/giftcodes/" & IF(ISNUMBER(LEFT(A30,1)*1), "game-", "") & A30 & ".html") -> https://www.ssbuy.tw/detail_giftcode/dist/giftcodes/救世者之樹：新世界.html | E30: 在重磅上線的樹緣系統中，舉行浪漫的樹緣典禮；集結戰友做好準備，迎戰魔神副本BOSS！ 新手可領取70抽、金色時裝4件套還有限定自選坐騎！ 讓我們來看看來自亞洲11地區的勇者們的留言！ -「日本韓國泰國的妹妹都搶著跟我結緣…好難選哦！」 --來自世界頻道的建巨集007號 樹緣系統重磅上線，在全服玩家的見證和祝福下，完成盛大浪漫的樹緣典禮！還會擁有一個共同的家園，一起創造美好生活！ | F30: 進入主畫面，點選個人頭像 | G30: 進入設定（齒輪） | H30: 輸入禮包碼 → 確認兌換 | K30: TOSNASIAN | L30: 貓靈扭蛋券 × 1、銀花 × 50000、強化卷軸 × 20 | M30: TOSN30DAYS | N30: 光珀 × 500、福袋禮票 × 10 | O30: LVVHKXYMBWPZ | P30: 貓票 × 2、光珀 × 100 | Q30: TOSNGIFT | R30: 2025商城元寶鑽石禮包 | S30: TOSN666 | T30: 2025商城元寶鑽石禮包 | U30: 2025GIFT | V30: 2025商城元寶鑽石禮包 | W30: TOSNNEKO | X30: 2025商城元寶鑽石禮包 | Y30: hello2025 | Z30: 2025商城元寶鑽石禮包
A31: 球球英雄 | B31: ="giftcodesbanner/" & A31 & "-bar.jpg" -> giftcodesbanner/球球英雄-bar.jpg | D31: =IF(A31="","", "https://www.ssbuy.tw/detail_giftcode/dist/giftcodes/" & IF(ISNUMBER(LEFT(A31,1)*1), "game-", "") & A31 & ".html") -> https://www.ssbuy.tw/detail_giftcode/dist/giftcodes/球球英雄.html | E31: 怪物們在這一天毫無預兆地突然降臨，城市與家園都籠罩在猙獰與陰霾中。 我們需要你，勇士！為我們抵禦黑暗勢力！ 來吧！和我們一起，召喚出賦有神奇力量的球球，與黑暗勢力戰鬥！ | F31: 進入主畫面，點選個人頭像 | G31: 進入設定（齒輪） | H31: 輸入禮包碼 → 確認兌換 | K31: E94LNYAM | L31: 2025商城元寶鑽石禮包 | M31: RM6G7HF4 | N31: 2025商城元寶鑽石禮包 | O31: VBGEW5JZ | P31: 2025商城元寶鑽石禮包
A32: 第七史詩 | B32: ="giftcodesbanner/" & A32 & "-bar.jpg" -> giftcodesbanner/第七史詩-bar.jpg | D32: =IF(A32="","", "https://www.ssbuy.tw/detail_giftcode/dist/giftcodes/" & IF(ISNUMBER(LEFT(A32,1)*1), "game-", "") & A32 & ".html") -> https://www.ssbuy.tw/detail_giftcode/dist/giftcodes/第七史詩.html | E32: 第七個世界的故事...生命的女神迪彩將自己的權勢瓜分，創造出聖約的繼承者及神獸 | F32: 進入主畫面，點選個人頭像 | G32: 進入設定（齒輪） | H32: 輸入禮包碼 → 確認兌換 | K32: THANKSHEIRALL | L32: 10片生命之葉 & 1,000,000金幣
A33: 創世紀戰M：阿修羅計畫 | B33: ="giftcodesbanner/" & A33 & "-bar.jpg" -> giftcodesbanner/創世紀戰M：阿修羅計畫-bar.jpg | D33: =IF(A33="","", "https://www.ssbuy.tw/detail_giftcode/dist/giftcodes/" & IF(ISNUMBER(LEFT(A33,1)*1), "game-", "") & A33 & ".html") -> https://www.ssbuy.tw/detail_giftcode/dist/giftcodes/創世紀戰M：阿修羅計畫.html | E33: 富饒廣闊的安塔利亞大陸，因戰爭爆發一切風雲變色，飽受戰爭欺凌， 王女伊歐林帶著王國騎士團，憑藉勇氣與智慧復國，對抗艱難命運。 面對強大武力的蓋席勒帝國，也絕不屈服！ | F33: 進入主畫面，點選個人頭像 | G33: 進入設定（齒輪） | H33: 輸入禮包碼 → 確認兌換 | K33: SHASHA77 | L33: 2025商城元寶鑽石禮包 | M33: HOWHOW | N33: 2025商城元寶鑽石禮包 | O33: GENESIS | P33: 2025商城元寶鑽石禮包 | Q33: Kr1stw | R33: 2025商城元寶鑽石禮包 | S33: GenesisGoogleHOT | T33: 2025商城元寶鑽石禮包 | U33: jazlatte | V33: 2025商城元寶鑽石禮包 | W33: roger9527 | X33: 2025商城元寶鑽石禮包 | Y33: greentea | Z33: 2025商城元寶鑽石禮包 | AA33: pudding1223xd | AB33: 2025商城元寶鑽石禮包 | AC33: COMMUTE | AD33: 2025商城元寶鑽石禮包 | AE33: ennaouii | AF33: 2025商城元寶鑽石禮包
A34: 最強宗師 | B34: ="giftcodesbanner/" & A34 & "-bar.jpg" -> giftcodesbanner/最強宗師-bar.jpg | D34: =IF(A34="","", "https://www.ssbuy.tw/detail_giftcode/dist/giftcodes/" & IF(ISNUMBER(LEFT(A34,1)*1), "game-", "") & A34 & ".html") -> https://www.ssbuy.tw/detail_giftcode/dist/giftcodes/最強宗師.html | E34: 《最強宗師》是一款最強卡牌策略RPG，在這裡，每位角色都有獨特特質，不存在廢卡，所有資源都能無損傳承，讓你輕鬆成為最強宗師！躺平掛機也能生產材料，輕鬆實現戰力飆升。策略搭配、多樣玩法，帶你領略充滿熱血與智慧的宗門修煉之路！在這裡，人人都可以是主角，天選之人，唯我最強！ | F34: 進入主畫面，點選個人頭像 | G34: 進入設定（齒輪） | H34: 輸入禮包碼 → 確認兌換 | K34: master111 | L34: 2025商城元寶鑽石禮包 | M34: top111 | N34: 2025商城元寶鑽石禮包 | O34: top666 | P34: 2025商城元寶鑽石禮包 | Q34: top777 | R34: 2025商城元寶鑽石禮包 | S34: top888 | T34: 2025商城元寶鑽石禮包 | U34: Ldtop666 | V34: 2025商城元寶鑽石禮包 | W34: Noxtop666 | X34: 2025商城元寶鑽石禮包 | Y34: Bluetop666 | Z34: 2025商城元寶鑽石禮包 | AA34: master666 | AB34: 2025商城元寶鑽石禮包 | AC34: master777 | AD34: 2025商城元寶鑽石禮包 | AE34: master888 | AF34: 2025商城元寶鑽石禮包 | AG34: master999 | AH34: 2025商城元寶鑽石禮包
A35: 無期迷途 | B35: ="giftcodesbanner/" & A35 & "-bar.jpg" -> giftcodesbanner/無期迷途-bar.jpg | D35: =IF(A35="","", "https://www.ssbuy.tw/detail_giftcode/dist/giftcodes/" & IF(ISNUMBER(LEFT(A35,1)*1), "game-", "") & A35 & ".html") -> https://www.ssbuy.tw/detail_giftcode/dist/giftcodes/無期迷途.html | E35: 《無期迷途》是款以混沌都市為主題的RPG即時策略攻防手遊。身為【米諾斯危機管理局】局長的你，將親手追蹤並收容擁有特殊力量的異能使者——禁閉者們。使用禁閉者的禁忌力量，揭開隱藏在這個世界的真相！ 「您好，新任的局長，我們一直都在等你。」這裡是米諾斯危機管理局，一座收容禁閉者的隱密場所。而您——令人尊敬的局長，將在此釋放其中最強大的禁閉者們。他們或舉止優雅，或性情乖張，或美艷狡猾；唯一的共同點他們都有不為人知的過去，以及超越常人的超凡之力。 局長，請盡情使用他們的力量，深入狄斯城的禁區，尋找讓世界異變的源頭，解開瘋狂恐怖謎團，去扭轉命運吧！ | F35: 進入主畫面，點選個人頭像 | G35: 進入設定（齒輪） | H35: 輸入禮包碼 → 確認兌換 | K35: 二週年快樂 | L35: 2025商城元寶鑽石禮包 | M35: 幽零風暴 | N35: 2025商城元寶鑽石禮包 | O35: 感謝一路相伴 | P35: 2025商城元寶鑽石禮包 | Q35: 白記實業發大財 | R35: 2025商城元寶鑽石禮包
A36: 絕區零 | B36: ="giftcodesbanner/" & A36 & "-bar.jpg" -> giftcodesbanner/絕區零-bar.jpg | D36: =IF(A36="","", "https://www.ssbuy.tw/detail_giftcode/dist/giftcodes/" & IF(ISNUMBER(LEFT(A36,1)*1), "game-", "") & A36 & ".html") -> https://www.ssbuy.tw/detail_giftcode/dist/giftcodes/絕區零.html | E36: 遊戲故事發生在被神秘災害「空洞」所侵襲的後世界末日世界中，主角是一位名為「繩匠」的角色，負責引導人們進入「空洞」並與怪物「以骸」戰鬥。 | F36: 進入主畫面，點選個人頭像 | G36: 進入設定（齒輪） | H36: 輸入禮包碼 → 確認兌換 | K36: HARUMASAGIFTALL | L36: 2025年可用兌換碼 | M36: ZZZ4PC | N36: 2024 PC 限定兌換碼 | O36: ZZZFM | P36: 2024 日本全家合作兌換碼 | Q36: ZZZGFN24 | R36: 2024 GeForce NOW x 絕區零 兌換碼 | S36: HSAHLWFEFE | T36: 2024年推出，仍可使用 | U36: ZENLESSGIFT | V36: 2024年推出，仍可使用 | W36: ZZZ15MINA | X36: 2025 1.5 版兌換碼
A37: 傳說對決 | B37: ="giftcodesbanner/" & A37 & "-bar.jpg" -> giftcodesbanner/傳說對決-bar.jpg | D37: =IF(A37="","", "https://www.ssbuy.tw/detail_giftcode/dist/giftcodes/" & IF(ISNUMBER(LEFT(A37,1)*1), "game-", "") & A37 & ".html") -> https://www.ssbuy.tw/detail_giftcode/dist/giftcodes/傳說對決.html | E37: Garena 傳說對決是一款節奏快速、輕鬆又不失競技成分的MOBA 手遊，經典玩法加上獨特的輪盤指向施法的直覺操作模式，輕鬆競技於指掌之間！ | F37: 進入主畫面，點選個人頭像 | G37: 進入設定（齒輪） | H37: 輸入禮包碼 → 確認兌換 | K37: HAPPY2025 | L37: 造型20選一 | M37: 2025AOV777 | N37: 光暗擊殺特效永久
A38: 楓之谷M | B38: ="giftcodesbanner/" & A38 & "-bar.jpg" -> giftcodesbanner/楓之谷M-bar.jpg | D38: =IF(A38="","", "https://www.ssbuy.tw/detail_giftcode/dist/giftcodes/" & IF(ISNUMBER(LEFT(A38,1)*1), "game-", "") & A38 & ".html") -> https://www.ssbuy.tw/detail_giftcode/dist/giftcodes/楓之谷M.html | E38: 《楓之谷M》是一款由Nexon開發的免費大型多人線上角色扮演遊戲，是基於《楓之谷》的移動版。 遊戲中玩家可以扮演來自各地的角色，進行冒險、戰鬥、任務、以及和其他玩家互動。 | F38: 進入主畫面，點選個人頭像 | G38: 進入設定（齒輪） | H38: 輸入禮包碼 → 確認兌換 | K38: 202501EREL | L38: 橘色經驗值增加券X5、自動戰鬥補充券X3、地城入場券組合 | M38: M2025NEWYEAR | N38: 蛇湯X2、自動戰鬥補充券X4、弄蛇人椅子X1 | O38: 202502ARCHON | P38: 2025商城元寶鑽石禮包 | Q38: AGAINHASTE | R38: 2025商城元寶鑽石禮包
A39: 鳴潮 | B39: ="giftcodesbanner/" & A39 & "-bar.jpg" -> giftcodesbanner/鳴潮-bar.jpg | D39: =IF(A39="","", "https://www.ssbuy.tw/detail_giftcode/dist/giftcodes/" & IF(ISNUMBER(LEFT(A39,1)*1), "game-", "") & A39 & ".html") -> https://www.ssbuy.tw/detail_giftcode/dist/giftcodes/鳴潮.html | E39: 《鳴潮》是一款末世題材的開放世界遊戲，具有高自由度且豐富的內容。 遊戲玩法包括攀爬、滑翔、採集等開放世界要素，還新增了「跑牆」的元素。 本作動作方面採用玩家能夠「閃避」和「彈刀」兩種招架方式。 | F39: 進入主畫面，點選個人頭像 | G39: 進入設定（齒輪） | H39: 輸入禮包碼 → 確認兌換 | K39: VCN9R5JONA6F | L39: 咪咪蛋 | M39: 8EHD24I802UP | N39: 大丸 | O39: QZ05OKNOB8FW | P39: 璐洛洛 | Q39: K82WZ34HXSJK | R39: 懶貓
A40: 劍與遠征：啟程 | B40: ="giftcodesbanner/" & A40 & "-bar.jpg" -> giftcodesbanner/劍與遠征：啟程-bar.jpg | D40: =IF(A40="","", "https://www.ssbuy.tw/detail_giftcode/dist/giftcodes/" & IF(ISNUMBER(LEFT(A40,1)*1), "game-", "") & A40 & ".html") -> https://www.ssbuy.tw/detail_giftcode/dist/giftcodes/劍與遠征：啟程.html | E40: 《劍與遠征：啟程》是一款全球多平台的輕鬆放置大世界RPG遊戲，由放置始祖《劍與遠征》開發團隊所打造。 玩家將集結超過百位不同能力、各具魅力的英雄夥伴，與他們一起探索名為「伊索米亞」的廣闊大世界，並逐漸揭開其中秘辛 | F40: 進入主畫面，點選個人頭像 | G40: 進入設定（齒輪） | H40: 輸入禮包碼 → 確認兌換 | K40: afkjoshikatsu | L40: 200鑽石和金幣 | M40: MAGICAFKJOURNEY | N40: 200鑽石+金幣 | O40: AFKJomedetou | P40: 1000鑽和20000金幣 | Q40: AFKJCREATOR | R40: 100鑽和18888金幣 | S40: AFKJCOMMUNITY | T40: 100鑽和10000金幣
...
